<?xml version="1.0"?>
<robot name="arm">
  <self_collide>false</self_collide>
  <link name="world"/>
  <link name="base_link">
    <visual>
      <geometry>
        <cylinder length="0.05" radius="0.1"/>
      </geometry>
      <material name="silver">
        <color rgba="0.75 0.75 0.75 1"/>
      </material>
      <origin rpy="0 0 0" xyz="0 0 0.025"/>
    </visual>
    <collision>
      <geometry>
        <cylinder length="0.05" radius="0.1"/>
      </geometry>
      <origin rpy="0 0 0" xyz="0 0 0.025"/>
    </collision>
    <inertial>
      <mass value="0.5"/>
      <origin rpy="0 0 0" xyz="0 0 0.025"/>
      <inertia ixx="0.0027" iyy="0.0027" izz="0.005" ixy="0" ixz="0" iyz="0"/>
    </inertial>
  </link>
  <joint name="fixed" type="fixed">
    <parent link="world"/>
    <child link="base_link"/>
  </joint>
  <link name="torso">
    <visual>
      <geometry>
        <cylinder length="0.084" radius="0.05"/>
      </geometry>
      <material name="silver">
        <color rgba="0.75 0.75 0.75 1"/>
      </material>
      <origin rpy="0 0 0" xyz="0 0 0.042"/>
    </visual>
    <collision>
      <geometry>
        <cylinder length="0.084" radius="0.05"/>
      </geometry>
      <origin rpy="0 0 0" xyz="0 0 0.042"/>
    </collision>
    <inertial>
      <mass value="0.5"/>
      <origin rpy="0 0 0" xyz="0 0 0.042"/>
      <inertia ixx="0.02146" iyy="0.02146" izz="0.00125" ixy="0" ixz="0" iyz="0"/>
    </inertial>
  </link>
  <joint name="hip" type="continuous">
    <axis xyz="0 0 1"/>
    <limit effort="1000" velocity="10.0"/>
    <parent link="base_link"/>
    <child link="torso"/>
    <origin rpy="0 0 0" xyz="0.0 0.0 0.05"/>
  </joint>
  <link name="upper_arm">
    <visual>
      <geometry>
        <cylinder length="0.5584" radius="0.05"/>
      </geometry>
      <material name="silver"/>
      <origin rpy="0 0 0" xyz="0 0 0.2792"/>
    </visual>
    <collision>
      <geometry>
        <cylinder length="0.5584" radius="0.05"/>
      </geometry>
      <origin rpy="0 0 0" xyz="0 0 0.2792"/>
    </collision>
    <inertial>
      <mass value="0.5"/>
      <origin rpy="0 0 0" xyz="0 0 0.2792"/>
      <inertia ixx="0.01396" iyy="0.01396" izz="0.00125" ixy="0" ixz="0" iyz="0"/>
    </inertial>
  </link>
  <joint name="shoulder" type="revolute">
    <axis xyz="0 1 0"/>
    <limit effort="1000" velocity="10.0" lower="-1.57" upper="0.1" />
    <parent link="torso"/>
    <child link="upper_arm"/>
    <origin rpy="0 1.5708 0" xyz="0.0 0 0.084"/>
  </joint>
  <link name="middle_arm">
    <visual>
      <geometry>
        <cylinder length="0.3673" radius="0.05"/>
      </geometry>
      <material name="silver"/>
      <origin rpy="0 0 0" xyz="0 0 0.18365"/>
    </visual>
    <collision>
      <geometry>
        <cylinder length="0.3673" radius="0.05"/>
      </geometry>
      <origin rpy="0 0 0" xyz="0 0 0.18365"/>
    </collision>
    <inertial>
      <mass value="0.5"/>
      <origin rpy="0 0 0" xyz="0 0 0.18365"/>
      <inertia ixx="0.01396" iyy="0.01396" izz="0.00125" ixy="0" ixz="0" iyz="0"/>
    </inertial>
  </link>
  <joint name="elbow" type="revolute">
    <axis xyz="0 1 0"/>
    <limit effort="1000" velocity="10.0" lower="0" upper="2.5" />
    <parent link="upper_arm"/>
    <child link="middle_arm"/>
    <origin rpy="0 0 0" xyz="0.0 0 0.5584"/>
  </joint>

  <link name="lower_arm">
    <visual>
      <geometry>
        <cylinder length="0.064" radius="0.05"/>
      </geometry>
      <material name="silver"/>
      <origin rpy="0 0 0" xyz="0 0 0.032"/>
    </visual>
    <collision>
      <geometry>
        <cylinder length="0.064" radius="0.05"/>
      </geometry>
      <origin rpy="0 0 0" xyz="0 0 0.032"/>
    </collision>
    <inertial>
      <mass value="0.5"/>
      <inertia ixx="0.00042" iyy="0.00042" izz="0.00042" ixy="0" ixz="0" iyz="0"/>
    </inertial>
  </link>
  <joint name="lower_elbow" type="revolute">
    <axis xyz="0 1 0"/>
    <limit effort="1000" velocity="10.0" lower="-1.9" upper="1.9" />
    <parent link="middle_arm"/>
    <child link="lower_arm"/>
    <origin rpy="0 0 0" xyz="0.0 0.0 0.3673"/>
  </joint>

  <link name="hand">
    <visual>
      <geometry>
        <box size="0.1 0.22 0.1025"/>
      </geometry>
      <material name="silver"/>
    </visual>
    <collision>
      <geometry>
        <box size="0.1 0.22 0.1025"/>
      </geometry>
    </collision>
    <inertial>
      <mass value="0.25"/>
      <inertia ixx="0.00042" iyy="0.00042" izz="0.00042" ixy="0" ixz="0" iyz="0"/>
    </inertial>
  </link>
  <joint name="wrist" type="continuous">
    <axis xyz="0 0 1"/>
    <limit effort="1000" velocity="10.0"/>
    <parent link="lower_arm"/>
    <child link="hand"/>
    <origin rpy="0 0 0" xyz="0.0 0.0 0.11525"/>
  </joint>
  <link name="grip_finger">
    <visual>
      <geometry>
        <box size="0.03 0.12 0.12"/>
      </geometry>
      <material name="silver"/>
    </visual>
    <collision>
      <geometry>
        <box size="0.22 0.1 0.22"/>
      </geometry>
    </collision>
    <inertial>
      <mass value="0.25"/>
      <inertia ixx="0.00042" iyy="0.00042" izz="0.00042" ixy="0" ixz="0" iyz="0"/>
    </inertial>
  </link>
  <joint name="grip" type="prismatic">
    <parent link="hand"/>
    <child link="grip_finger"/>
    <limit effort="1000.0" lower="-0.175" upper="0" velocity="0.5"/>
    <origin rpy="0 0 1.57075" xyz="0.0 0.075 0.11525"/>
  </joint>
  <link name="grip_fixed">
    <visual>
      <geometry>
        <box size="0.03 0.12 0.12"/>
      </geometry>
      <material name="silver"/>
    </visual>
    <collision>
      <geometry>
        <box size="0.22 0.1 0.22"/>
      </geometry>
    </collision>
    <inertial>
      <mass value="0.1"/>
      <inertia ixx="5.1458e-5" iyy="5.1458e-5" izz="6.125e-5" ixy="0" ixz="0" iyz="0"/>
    </inertial>
  </link>
  <joint name="grip_base_to_fixed" type="fixed">
    <parent link="hand"/>
    <child link="grip_fixed"/>
    <origin rpy="0 0 1.57075" xyz="0.0 -0.096 0.11525"/>
  </joint>
  <transmission name="tran0">
    <type>transmission_interface/SimpleTransmission</type>
    <joint name="hip">
      <hardwareInterface>PositionJointInterface</hardwareInterface>
    </joint>
    <actuator name="motor0">
      <hardwareInterface>PositionJointInterface</hardwareInterface>
      <mechanicalReduction>1</mechanicalReduction>
    </actuator>
  </transmission>
  <transmission name="tran1">
    <type>transmission_interface/SimpleTransmission</type>
    <joint name="shoulder">
      <hardwareInterface>PositionJointInterface</hardwareInterface>
    </joint>
    <actuator name="motor1">
      <hardwareInterface>PositionJointInterface</hardwareInterface>
      <mechanicalReduction>1</mechanicalReduction>
    </actuator>
  </transmission>
  <transmission name="tran2">
    <type>transmission_interface/SimpleTransmission</type>
    <joint name="elbow">
      <hardwareInterface>PositionJointInterface</hardwareInterface>
    </joint>
    <actuator name="motor2">
      <hardwareInterface>PositionJointInterface</hardwareInterface>
      <mechanicalReduction>1</mechanicalReduction>
    </actuator>
  </transmission>
  <transmission name="tran3">
    <type>transmission_interface/SimpleTransmission</type>
    <joint name="wrist">
      <hardwareInterface>PositionJointInterface</hardwareInterface>
    </joint>
    <actuator name="motor3">
      <hardwareInterface>PositionJointInterface</hardwareInterface>
      <mechanicalReduction>1</mechanicalReduction>
    </actuator>
  </transmission>
  <transmission name="tran4">
    <type>transmission_interface/SimpleTransmission</type>
    <joint name="grip">
      <hardwareInterface>PositionJointInterface</hardwareInterface>
    </joint>
    <actuator name="motor4">
      <hardwareInterface>PositionJointInterface</hardwareInterface>
      <mechanicalReduction>1</mechanicalReduction>
    </actuator>
  </transmission>
  <transmission name="tran5">
    <type>transmission_interface/SimpleTransmission</type>
    <joint name="lower_elbow">
      <hardwareInterface>PositionJointInterface</hardwareInterface>
    </joint>
    <actuator name="motor5">
      <hardwareInterface>PositionJointInterface</hardwareInterface>
      <mechanicalReduction>1</mechanicalReduction>
    </actuator>
  </transmission>
  <gazebo>
    <plugin name="control" filename="libgazebo_ros_control.so"/>
  </gazebo>
  <gazebo>
    <plugin name="joint_state_publisher" filename="libgazebo_ros_joint_state_publisher.so">
      <jointName>hip, shoulder, elbow, lower_elbow, wrist, grip</jointName>
    </plugin>
  </gazebo>
</robot>
