<?xml version="1.0"?>
<robot name="URC">
  <link name="world"/>
 
  <link name="base_link">
    <visual>
      <geometry>
        <cylinder length="0.0" radius="0.05"/>
      </geometry>
      <material name="silver">
        <color rgba="0.75 0.75 0.75 1"/>
      </material>
      <origin rpy="0 0 0" xyz="0 0 0.025"/>
    </visual>
    <collision>
      <geometry>
        <cylinder length="0.05" radius="0.1"/>
      </geometry>
      <origin rpy="0 0 0" xyz="0 0 0.025"/>
    </collision>
    <inertial>
      <mass value="1.0"/>
      <origin rpy="0 0 0" xyz="0 0 0.025"/>
      <inertia ixx="0.0027" iyy="0.0027" izz="0.005" ixy="0" ixz="0" iyz="0"/>
    </inertial>
  </link>

  <joint name="fixed" type="fixed">
    <parent link="world"/>
    <child link="base_link"/>
  </joint>

  <link name="torso">
    <visual>
      <geometry>
        <cylinder length="0.084" radius="0.05"/>
      </geometry>
      <material name="silver">
        <color rgba="0.75 0.75 0.75 1"/>
      </material>
      <origin rpy="0 0 0" xyz="0 0 0.042"/>
    </visual>
    <collision>
      <geometry>
        <cylinder length="0.084" radius="0.05"/>
      </geometry>
      <origin rpy="0 0 0" xyz="0 0 0.042"/>
    </collision>
    <inertial>
      <mass value="1.0"/>
      <origin rpy="0 0 0" xyz="0 0 0.042"/>
      <inertia ixx="0.02146" iyy="0.02146" izz="0.00125" ixy="0" ixz="0" iyz="0"/>
    </inertial>
  </link>

  <joint name="base_twist" type="continuous">
    <axis xyz="0 0 1"/>
    <parent link="base_link"/>
    <child link="torso"/>
    <origin rpy="0 0 0" xyz="0.0 0.0 0.0"/>
    
  </joint>

  <link name="middle_arm">
    <visual>
      <geometry>
        <cylinder length="0.5584" radius="0.05"/>
      </geometry>
      <material name="silver"/>
      <origin rpy="0 0 0" xyz="0 0 0.2792"/>
    </visual>
    <collision>
      <geometry>
        <cylinder length="0.5584" radius="0.05"/>
      </geometry>
      <origin rpy="0 0 0" xyz="0 0 0.2792"/>
    </collision>
    <inertial>
      <mass value="1.0"/>
      <origin rpy="0 0 0" xyz="0 0 0.2792"/>
      <inertia ixx="0.01396" iyy="0.01396" izz="0.00125" ixy="0" ixz="0" iyz="0"/>
    </inertial>
  </link>

  <joint name="elbow_lower" type="revolute">
    <axis xyz="0 1 0"/>
    <parent link="torso"/>
    <child link="middle_arm"/>
    <origin rpy="0 1.5708 0" xyz="0.0 0 0.084"/>
    <limit effort="30" velocity="1.0" lower="0.698" upper="-1.396" />
  </joint>

  <link name="lower_arm">
    <visual>
      <geometry>
        <cylinder length="0.3673" radius="0.05"/>
      </geometry>
      <material name="silver"/>
      <origin rpy="0 0 0" xyz="0 0 0.18365"/>
    </visual>
    <collision>
      <geometry>
        <cylinder length="0.3673" radius="0.05"/>
      </geometry>
      <origin rpy="0 0 0" xyz="0 0 0.18365"/>
    </collision>
    <inertial>
      <mass value="1.0"/>
      <origin rpy="0 0 0" xyz="0 0 0.18365"/>
      <inertia ixx="0.01396" iyy="0.01396" izz="0.00125" ixy="0" ixz="0" iyz="0"/>
    </inertial>
  </link>

  <joint name="elbow_middle" type="revolute">
    <axis xyz="0 1 0"/>
    <parent link="middle_arm"/>
    <child link="lower_arm"/>
    <origin rpy="0 0 0" xyz="0.0 0 0.5584"/>
    <limit effort="1000.0" lower="2.96706" upper="1.31" velocity="0.5"/>
  </joint>

  <link name="upper_arm">
    <visual>
      <geometry>
        <cylinder length="0.064" radius="0.05"/>
      </geometry>
      <material name="silver"/>
      <origin rpy="0 0 0" xyz="0 0 0.032"/>
    </visual>
    <collision>
      <geometry>
        <cylinder length="0.064" radius="0.05"/>
      </geometry>
      <origin rpy="0 0 0" xyz="0 0 0.032"/>
    </collision>
    <inertial>
      <mass value="1.0"/>
      <inertia ixx="0.00042" iyy="0.00042" izz="0.00042" ixy="0" ixz="0" iyz="0"/>
    </inertial>
  </link>

  <joint name="elbow_upper" type="revolute">
    <axis xyz="0 1 0"/>
    <parent link="lower_arm"/>
    <child link="upper_arm"/>
    <origin rpy="0 0 0" xyz="0.0 0.0 0.3673"/>
    <limit effort="1000.0" lower="-2.00713" upper="2.00713" velocity="0.5"/>
  </joint>

  <link name="grip_base">
    <visual>
      <geometry>
        <box size="0.1 0.22 0.1025"/>
      </geometry>
      <material name="silver"/>
    </visual>
    <collision>
      <geometry>
        <box size="0.1 0.22 0.1025"/>
      </geometry>
    </collision>
  </link>

  <joint name="grip_twist" type="continuous">
    <axis xyz="0 0 1"/>
    <parent link="upper_arm"/>
    <child link="grip_base"/>
    <origin rpy="0 0 0" xyz="0.0 0.0 0.11525"/>
  </joint>

  <link name="grip_fixed">
    <visual>
      <geometry>
        <box size="0.03 0.1 0.08"/>
      </geometry>
      <material name="silver"/>
    </visual>
    <collision>
      <geometry>
        <box size="0.22 0.1 0.22"/>
      </geometry>
    </collision>
  </link>

  <joint name="grip_base_to_fixed" type="fixed">
    <parent link="grip_base"/>
    <child link="grip_fixed"/>
    <origin rpy="0 0 1.57075" xyz="0.0 0.096 0.09125"/>
  </joint>

  <link name="grip_finger">
    <visual>
      <geometry>
        <box size="0.03 0.1 0.08"/>
      </geometry>
      <material name="silver"/>
    </visual>
    <collision>
      <geometry>
        <box size="0.22 0.1 0.22"/>
      </geometry>
    </collision>
  </link>

  <joint name="grip" type="prismatic">
    <parent link="grip_base"/>
    <child link="grip_finger"/>
    <limit effort="1000.0" lower="-0.175" upper="0" velocity="0.5"/>
    <origin rpy="0 0 1.57075" xyz="0.0 0.075 0.09125"/>
  </joint>

  <transmission name="tran0">
    <type>transmission_interface/SimpleTransmission</type>
    <joint name="base_twist">
      <hardwareInterface>PositionJointInterface</hardwareInterface>
    </joint>
    <actuator name="motor0">
      <hardwareInterface>PositionJointInterface</hardwareInterface>
      <mechanicalReduction>1</mechanicalReduction>
    </actuator>
  </transmission>
  <transmission name="tran1">
    <type>transmission_interface/SimpleTransmission</type>
    <joint name="elbow_lower">
      <hardwareInterface>PositionJointInterface</hardwareInterface>
    </joint>
    <actuator name="motor1">
      <hardwareInterface>PositionJointInterface</hardwareInterface>
      <mechanicalReduction>1</mechanicalReduction>
    </actuator>
  </transmission>
  <transmission name="tran2">
    <type>transmission_interface/SimpleTransmission</type>
    <joint name="elbow_middle">
      <hardwareInterface>PositionJointInterface</hardwareInterface>
    </joint>
    <actuator name="motor2">
      <hardwareInterface>PositionJointInterface</hardwareInterface>
      <mechanicalReduction>1</mechanicalReduction>
    </actuator>
  </transmission>
  <transmission name="tran3">
    <type>transmission_interface/SimpleTransmission</type>
    <joint name="elbow_upper">
      <hardwareInterface>PositionJointInterface</hardwareInterface>
    </joint>
    <actuator name="motor3">
      <hardwareInterface>PositionJointInterface</hardwareInterface>
      <mechanicalReduction>1</mechanicalReduction>
    </actuator>
  </transmission>
  <gazebo>
    <plugin name="control" filename="libgazebo_ros_control.so"/>
  </gazebo>
  <gazebo>
    <plugin name="joint_state_publisher" filename="libgazebo_ros_joint_state_publisher.so">
      <jointName>base_twist, elbow_lower, elbow_middle, elbow_upper</jointName>
    </plugin>
  </gazebo>
</robot>





